Workbook

Sheet KKLEAD_SPIP
C3: PENJAMINAN KUALITAS HASIL PENILAIAN MANDIRI MATURITAS PENYELENGGARAAN SPIP TERINTEGRASI KEMENTERIAN KOMUNIKASI DAN DIGITAL Periode Penilaian sampai dengan 20 Agustus 2025
C4: PENYIMPULAN NILAI MATURITAS PENYELENGGARAAN SPIP TERINTEGRASI
C6: Komponen, Unsur, dan Subunsur | D6: Skor PM | E6: Skor PK | F6: Bobot Unsur | G6: Bobot Komponen | H6: Nilai Unsur | I6: Nilai Komponen | J6: Nilai Akhir
C8: PENETAPAN TUJUAN
C9: Kualitas Sasaran Strategis | E9: ='KKlead I KL'!I20 -> 4 | F9: 0.5 | H9: =E9*F9 -> 2
C10: Kualitas Strategi Pencapaian Sasaran Strategis | E10: ='KKlead I KL'!I44 -> 5 | F10: 0.5 | H10: =E10*F10 -> 2.5
C11: SUB JUMLAH PERENCANAAN | F11: =SUM(F9:F10) -> 1 | H11: =SUM(H9:H10) -> 4.5
C12: BOBOT PERENCANAAN | G12: 0.4 | I12: =$G$12*$H$11 -> 1.8
C14: STRUKTUR DAN PROSES
C15: Lingkungan Pengendalian
C16: Penegakan Integritas dan Nilai Etika (1.1) | E16: ='KKLEAD II'!L6 -> 4.09375 | F16: =30%/8 -> 0.0375 | H16: =E16*F16 -> 0.15351562
C17: Komitmen terhadap Kompetensi (1.2) | E17: ='KKLEAD II'!L15 -> 3.5 | F17: =30%/8 -> 0.0375 | H17: =E17*F17 -> 0.13125
C18: Kepemimpinan yang Kondusif (1.3) | E18: ='KKLEAD II'!L17 -> 3 | F18: =30%/8 -> 0.0375 | H18: =E18*F18 -> 0.1125
C19: Pembentukan Struktur Organisasi yang Sesuai dengan Kebutuhan (1.4) | E19: ='KKLEAD II'!L25 -> 3.75 | F19: =30%/8 -> 0.0375 | H19: =E19*F19 -> 0.140625
C20: Pendelegasian Wewenang dan Tanggung Jawab yang Tepat (1.5) | E20: ='KKLEAD II'!L27 -> 4.75 | F20: =30%/8 -> 0.0375 | H20: =E20*F20 -> 0.178125
C21: Penyusunan dan Penerapan Kebijakan yang Sehat tentang Pembinaan SDM (1.6) | E21: ='KKLEAD II'!L29 -> 2.75 | F21: =30%/8 -> 0.0375 | H21: =E21*F21 -> 0.103125
C22: Perwujudan Peran APIP yang Efektif (1.7) | E22: ='KKLEAD II'!L33 -> 3 | F22: =30%/8 -> 0.0375 | H22: =E22*F22 -> 0.1125
C23: Hubungan Kerja yang Baik dengan Instansi Pemerintah Terkait (1.8) | E23: ='KKLEAD II'!L35 -> 3.625 | F23: =30%/8 -> 0.0375 | H23: =E23*F23 -> 0.1359375
C24: Penilaian Risiko
C25: Identifikasi Risiko (2.1) | E25: ='KKLEAD II'!L38 -> 2.8333333 | F25: 0.1 | H25: =E25*F25 -> 0.28333333
C26: Analisis Risiko (2.2) | E26: ='KKLEAD II'!L42 -> 2.95 | F26: 0.1 | H26: =E26*F26 -> 0.295
C27: Kegiatan Pengendalian
C28: Reviu atas Kinerja Instansi Pemerintah (3.1) | E28: ='KKLEAD II'!L49 -> 3 | F28: =25%/11 -> 0.022727273 | H28: =E28*F28 -> 0.068181818
C29: Pembinaan Sumber Daya Manusia (3.2) | E29: ='KKLEAD II'!L51 -> 4 | F29: =25%/11 -> 0.022727273 | H29: =E29*F29 -> 0.090909091
C30: Pengendalian atas Pengelolaan Sistem Informasi (3.3) | E30: ='KKLEAD II'!L53 -> 3.5 | F30: =25%/11 -> 0.022727273 | H30: =E30*F30 -> 0.079545455
C31: Pengendalian Fisik atas Aset (3.4) | E31: ='KKLEAD II'!L55 -> 4 | F31: =25%/11 -> 0.022727273 | H31: =E31*F31 -> 0.090909091
C32: Penetapan dan Reviu atas Indikator dan Ukuran Kinerja (3.5) | E32: ='KKLEAD II'!L57 -> 3.5 | F32: =25%/11 -> 0.022727273 | H32: =E32*F32 -> 0.079545455
C33: Pemisahan Fungsi (3.6) | E33: ='KKLEAD II'!L59 -> 3.25 | F33: =25%/11 -> 0.022727273 | H33: =E33*F33 -> 0.073863636
C34: Otorisasi atas Transaksi dan Kejadian yang Penting (3.7) | E34: ='KKLEAD II'!L61 -> 3.25 | F34: =25%/11 -> 0.022727273 | H34: =E34*F34 -> 0.073863636
C35: Pencatatan yang Akurat dan Tepat Waktu atas Transaksi dan Kejadian (3.8) | E35: ='KKLEAD II'!L63 -> 4 | F35: =25%/11 -> 0.022727273 | H35: =E35*F35 -> 0.090909091
C36: Pembatasan Akses atas Sumber Daya dan Pencatatannya (3.9) | E36: ='KKLEAD II'!L65 -> 3.5 | F36: =25%/11 -> 0.022727273 | H36: =E36*F36 -> 0.079545455
C37: Akuntabilitas terhadap Sumber Daya dan Pencatatannya (3.10) | E37: ='KKLEAD II'!L67 -> 3.75 | F37: =25%/11 -> 0.022727273 | H37: =E37*F37 -> 0.085227273
C38: Dokumentasi yang Baik atas SPI serta Transaksi dan Kejadian Penting (3.11) | E38: ='KKLEAD II'!L69 -> 3.5 | F38: =25%/11 -> 0.022727273 | H38: =E38*F38 -> 0.079545455
C39: Informasi dan Komunikasi
C40: Informasi yang Relevan (4.1) | E40: ='KKLEAD II'!L71 -> 3.05 | F40: 0.05 | H40: =E40*F40 -> 0.1525
C41: Komunikasi yang Efektif (4.2) | E41: ='KKLEAD II'!L77 -> 3 | F41: 0.05 | H41: =E41*F41 -> 0.15
C42: Pemantauan
C43: Pemantauan Berkelanjutan (5.1) | E43: ='KKLEAD II'!L79 -> 3.0833333 | F43: 0.075 | H43: =E43*F43 -> 0.23125
C44: Evaluasi Terpisah (5.2) | E44: ='KKLEAD II'!L83 -> 2.625 | F44: 0.075 | H44: =E44*F44 -> 0.196875
C45: SUB JUMLAH STRUKTUR DAN PROSES | H45: =SUM(H16:H44) -> 3.2685819
...

Sheet KKLEAD II
A1: PENJAMINAN KUALITAS HASIL PENILAIAN MANDIRI MATURITAS PENYELENGGARAAN SPIP PEMERINTAH DAERAH … Periode Penilaian 01 Juli 20XX-1 sampai dengan 30 Juni 20XX
A2: KERTAS KERJA PENILAIAN STRUKTUR DAN PROSES KK LEAD II - STRUKTUR DAN PROSES | L2: Indeks KK No. Disusun oleh/Tanggal Direviu oleh/Tanggal Disetujui oleh/Tanggal | M2: : : : :
A3: Kode | B3: Uraian Subunsur | C3: No | D3: Uraian Parameter | E3: Kode Parameter | H3: 2E NILAI | I3: KEUANGAN NILAI | J3: ASET NILAI | K3: KETAATAN NILAI | L3: KESIMPULAN NILAI | M3: VETO (YA/TIDAK) | N3: NILAI AKHIR | O3: KETERANGAN / CATATAN
E4: SPIP | F4: MRI | G4: IEPK
A6: 1.1 | B6: Penegakan Integritas dan Nilai Etika | H6: =AVERAGE(H7:H14) -> 3 | I6: =AVERAGE(I7:I14) -> 5 | J6: =AVERAGE(J7:J14) -> 5 | K6: =AVERAGE(K7:K14) -> 3.375 | L6: ='Uraian NIlai Setiap Unsur'!I5 -> 4.09375 | M6: =KK4_PENALTI!C5 -> TIDAK | N6: =IF(M6="YA",KK4_PENALTI!D5,L6) -> 4.09375
A7: 1.1 | C7: 1 | D7: Organisasi menegakkan integritas dan nilai etika dalam melaksanakan tugas dan fungsi organisasi Organisasi menegakkan integritas dan nilai etika dalam pengelolaan keuangan Organisasi menegakkan integritas dan nilai etika dalam pengelolaan aset Organisasi menegakkan integritas dan nilai etika dalam pelaksanaan tugasnya sesuai peraturan yang berlaku | E7: SPIP | F7: - | G7: - | H7: =KK3.1!S6 -> 3 | I7: =KK3.2!N7 -> 5 | J7: =KK3.3!N6 -> 5 | K7: =KK3.4!N6 -> 5 | L7: =AVERAGE(H7:K7) -> 4.5 | N7: =IF(AND($M$6="YA",L7>$N$6),$N$6,L7) -> 4.5
A8: 1.1 | C8: 2 | D8: Kebijakan eksplisit atas pengendalian korupsi yang mencakup pernyataan kebijakan, penetapan struktur pengelola risiko korupsi, serta standar perilaku antikorupsi | E8: SPIP | F8: - | G8: IEPK | K8: =KK3.4!N11 -> 3 | L8: =AVERAGE(H8:K8) -> 3 | N8: =IF(AND($M$6="YA",L8>$N$6),$N$6,L8) -> 3
A9: 1.1 | C9: 3 | D9: Organisasi menetapkan dan melaksanakan SOP antikorupsi yang mencakup tiga proses prinsip dalam pengelolaan risiko korupsi, yakni cegah, deteksi, dan respons. | E9: SPIP | F9: - | G9: IEPK | K9: =KK3.4!N16 -> 3 | L9: =AVERAGE(H9:K9) -> 3 | N9: =IF(AND($M$6="YA",L9>$N$6),$N$6,L9) -> 3
A10: 1.1 | C10: 4 | D10: Unit kerja sebagai lingkungan belajar dikelola untuk memungkinkan pegawai di semua level berpartisipasi dalam program antikorupsi dengan menghindari perilaku koruptif dan menunjukkan sikap lugas ketika berhadapan dengan situasi yang memicu perilaku korupsi | E10: SPIP | F10: - | G10: IEPK | K10: =KK3.4!N21 -> 3 | L10: =AVERAGE(H10:K10) -> 3 | N10: =IF(AND($M$6="YA",L10>$N$6),$N$6,L10) -> 3
A11: 1.1 | C11: 5 | D11: Integritas organisasional yang terwujud dalam transparansi dan akuntabilitas telah tercermin dalam visi, misi, tujuan, dan nilai-nilai organisasi/unit kerja | E11: SPIP | F11: - | G11: IEPK | K11: =KK3.4!N26 -> 3 | L11: =AVERAGE(H11:K11) -> 3 | N11: =IF(AND($M$6="YA",L11>$N$6),$N$6,L11) -> 3
A12: 1.1 | C12: 6 | D12: Terdapat persepsi bersama bahwa yang dijadikan acuan utama sebagai perilaku etis adalah peraturan, SOP, hukum, atau standar profesional | E12: SPIP | F12: - | G12: IEPK | K12: =KK3.4!N31 -> 3 | L12: =AVERAGE(H12:K12) -> 3 | N12: =IF(AND($M$6="YA",L12>$N$6),$N$6,L12) -> 3
A13: 1.1 | C13: 7 | D13: Kejadian korupsi/perilaku koruptif telah ditindaklanjuti oleh orang yang kompeten dan independen | E13: SPIP | F13: - | G13: IEPK | K13: =KK3.4!N36 -> 4 | L13: =AVERAGE(H13:K13) -> 4 | N13: =IF(AND($M$6="YA",L13>$N$6),$N$6,L13) -> 4
A14: 1.1 | C14: 8 | D14: Atas hasil audit atau investigasi telah diambil langkah dalam rangka memperbaiki kerusakan yang ditimbulkan oleh praktik korupsi di dalam organisasi berupa pemastian pengenaan sanksi dan perbaikan melalui pemulihan kerugian dan peningkatan pengendalian. | E14: SPIP | F14: - | G14: IEPK | K14: =KK3.4!N41 -> 3 | L14: =AVERAGE(H14:K14) -> 3 | N14: =IF(AND($M$6="YA",L14>$N$6),$N$6,L14) -> 3
A15: 1.2 | B15: Komitmen terhadap Kompetensi | H15: =H16 -> 4 | I15: =I16 -> 3 | J15: =J16 -> 3 | K15: =K16 -> 4 | L15: =AVERAGE(H15:K15) -> 3.5 | M15: =KK4_PENALTI!C6 -> TIDAK | N15: =IF(M15="YA",KK4_PENALTI!D6,L15) -> 3.5
A16: 1.2 | C16: 1 | D16: Tugas dan jabatan dalam organisasi dilaksanakan dan diisi oleh SDM yang kompeten | E16: SPIP | F16: - | G16: - | H16: =KK3.1!V12 -> 4 | I16: =KK3.2!N13 -> 3 | J16: =KK3.3!N12 -> 3 | K16: =KK3.4!N47 -> 4 | L16: =AVERAGE(H16:K16) -> 3.5 | N16: =IF($M$15="YA",$N$15,L16) -> 3.5
A17: 1.3 | B17: Kepemimpinan yang Kondusif | H17: =AVERAGE(H18:H24) -> 3.25 | I17: =AVERAGE(I18:I24) -> 3 | J17: =AVERAGE(J18:J24) -> 2.75 | K17: =AVERAGE(K18:K24) -> 3 | L17: =AVERAGE(H17:K17) -> 3 | M17: =KK4_PENALTI!C7 -> TIDAK | N17: =IF(M17="YA",KK4_PENALTI!D7,L17) -> 3
A18: 1.3 | C18: 1 | D18: Pimpinan organisasi menciptakan lingkungan kerja yang kondusif untuk pencapaian tujuan organisasi. | E18: SPIP | F18: - | G18: - | H18: =KK3.1!S18 -> 4 | I18: =KK3.2!N19 -> 4 | J18: =KK3.3!N18 -> 3 | K18: =KK3.4!N53 -> 3 | L18: =AVERAGE(H18:K18) -> 3.5 | N18: =IF($M$17="YA",$N$17,L18) -> 3.5
A19: 1.3 | C19: 2 | D19: Pimpinan Instansi Pemerintah mengalokasikan sumber daya untuk penerapan manajemen risiko. | E19: SPIP | F19: MRI | G19: - | H19: =KK3.1!S23 -> 3 | I19: =KK3.2!N24 -> 3 | J19: =KK3.3!N23 -> 3 | K19: =KK3.4!N58 -> 3 | L19: =AVERAGE(H19:K19) -> 3 | N19: =IF($M$17="YA",$N$17,L19) -> 3 | P19: KEPEMIMPINAN
A20: 1.3 | C20: 3 | D20: Pimpinan Instansi Pemerintah menggunakan informasi terkait risiko dalam pengambilan keputusan | E20: SPIP | F20: MRI | G20: - | H20: =KK3.1!S28 -> 3 | I20: =KK3.2!N29 -> 2 | J20: =KK3.3!N28 -> 2 | K20: =KK3.4!N63 -> 3 | L20: =AVERAGE(H20:K20) -> 2.5 | N20: =IF($M$17="YA",$N$17,L20) -> 2.5 | P20: KEPEMIMPINAN
A21: 1.3 | C21: 4 | D21: Pimpinan Instansi Pemerintah mendorong penerapan manajemen risiko, melalui Penggunaan kinerja penerapan manajemen risiko sebagai indikator penilaian kinerja | E21: SPIP | F21: MRI | G21: - | H21: =KK3.1!S33 -> 3 | I21: =KK3.2!N34 -> 3 | J21: =KK3.3!N33 -> 3 | K21: =KK3.4!N68 -> 3 | L21: =AVERAGE(H21:K21) -> 3 | N21: =IF($M$17="YA",$N$17,L21) -> 3 | P21: KEPEMIMPINAN
C22: 5 | D22: Program antikorupsi didukung dengan penyediaan alokasi sumberdaya secara eksplisit secara memadai, baik anggaran, personil, dan sarana prasarana | E22: SPIP | F22: - | G22: IEPK | K22: =KK3.4!N73 -> 3 | L22: =AVERAGE(H22:K22) -> 3 | N22: =IF($M$17="YA",$N$17,L22) -> 3
C23: 6 | D23: Faktor kekuasaan dan wewenang yang melekat pada pimpinan unit kerja dipakai untuk tujuan mengelola risiko korupsi secara efektif (tidak membiarkan/ mengabaikan) | E23: SPIP | F23: - | G23: IEPK | K23: =KK3.4!N78 -> 3 | L23: =AVERAGE(H23:K23) -> 3 | N23: =IF($M$17="YA",$N$17,L23) -> 3
C24: 7 | D24: Pimpinan mendorong bawahan untuk mengikutinya melalui atensi yang diberikan di berbagai kesempatan, keterbukaan dan transparansi, reinforcement, perlakuan adil, dan pengambilan keputusan yang menyertakan pertimbangan etis. | E24: SPIP | F24: - | G24: IEPK | K24: =KK3.4!N83 -> 3 | L24: =AVERAGE(H24:K24) -> 3 | N24: =IF($M$17="YA",$N$17,L24) -> 3
A25: 1.4 | B25: Struktur Organisasi Sesuai Kebutuhan | H25: =H26 -> 4 | I25: =I26 -> 4 | J25: =J26 -> 4 | K25: =K26 -> 3 | L25: =AVERAGE(H25:K25) -> 3.75 | M25: =KK4_PENALTI!C8 -> TIDAK | N25: =IF(M25="YA",KK4_PENALTI!D8,L25) -> 3.75
A26: 1.4 | C26: 1 | D26: Struktur organisasi dibentuk dalam rangka mendukung pencapaian sasaran strategis organisasi. Struktur organisasi dibentuk dalam rangka mendukung pencapaian keandalan laporan keuangan Struktur organisasi dibentuk dalam rangka mendukung pencapaian keamanan aset Dalam Struktur organisasi terdapat unit yang melaksanakan fungsi kepatuhan internal. | E26: SPIP | F26: - | G26: - | H26: =KK3.1!S39 -> 4 | I26: =KK3.2!N40 -> 4 | J26: =KK3.3!N39 -> 4 | K26: =KK3.4!N89 -> 3 | L26: =AVERAGE(H26:K26) -> 3.75 | N26: =IF($M$25="YA",$N$25,L26) -> 3.75
A27: 1.5 | B27: Pendelegasian Wewenang dan Tanggung Jawab yang Tepat | H27: =H28 -> 5 | I27: =I28 -> 5 | J27: =J28 -> 5 | K27: =K28 -> 4 | L27: =AVERAGE(H27:K27) -> 4.75 | M27: =KK4_PENALTI!C9 -> TIDAK | N27: =IF(M27="YA",KK4_PENALTI!D9,L27) -> 4.75
A28: 1.5 | C28: 1 | D28: Wewenang dan tanggung jawab diberikan kepada pegawai yang tepat sesuai tingkatannya untuk mendukung efektivitas dan efisiensi pelaksanaan kegiatan dalam rangka percepatan pencapaian tujuan organisasi. Pendelegasian Wewenang dan Tanggung Jawab memperhatikan benturan kepentingan | E28: SPIP | F28: - | G28: - | H28: =KK3.1!S45 -> 5 | I28: =KK3.2!N46 -> 5 | J28: =KK3.3!N45 -> 5 | K28: =KK3.4!N95 -> 4 | L28: =AVERAGE(H28:K28) -> 4.75 | N28: =IF($M$27="YA",$N$27,L28) -> 4.75
A29: 1.6 | B29: Penyusunan dan Penerapan Kebijakan yang Sehat tentang Pembinaan SDM | H29: =AVERAGE(H30:H32) -> 3 | I29: =AVERAGE(I30:I32) -> 2 | J29: =AVERAGE(J30:J32) -> 3 | K29: =AVERAGE(K30:K32) -> 3 | L29: =AVERAGE(H29:K29) -> 2.75 | M29: =KK4_PENALTI!C10 -> TIDAK | N29: =IF(M29="YA",KK4_PENALTI!D10,L29) -> 2.75
A30: 1.6 | C30: 1 | D30: Penerapan kebijakan manajemen dan praktik pembinaan SDM sehingga dapat digunakan secara maksimal untuk mencapai tujuan organisasi | E30: SPIP | F30: - | G30: - | H30: =KK3.1!S51 -> 3 | I30: =KK3.2!N52 -> 2 | J30: =KK3.3!N51 -> 5 | K30: =KK3.4!N101 -> 3 | L30: =AVERAGE(H30:K30) -> 3.25 | N30: =IF($M$29="YA",$N$29,L30) -> 3.25
A31: 1.6 | C31: 2 | D31: Pegawai telah mendapatkan fasilitas untuk meningkatkan kompetensi dan keterampilan terkait manajemen risiko | E31: SPIP | F31: MRI | G31: - | H31: =KK3.1!S56 -> 3 | I31: =KK3.2!N57 -> 2 | J31: =KK3.3!N56 -> 2 | K31: =KK3.4!N106 -> 3 | L31: =AVERAGE(H31:K31) -> 2.5 | N31: =IF($M$29="YA",$N$29,L31) -> 2.5 | P31: SDM
A32: 1.6 | C32: 3 | D32: Pegawai memiliki kesadaran terkait manajemen risiko | E32: SPIP | F32: MRI | G32: - | H32: =KK3.1!S61 -> 3 | I32: =KK3.2!N62 -> 2 | J32: =KK3.3!N61 -> 2 | K32: =KK3.4!N111 -> 3 | L32: =AVERAGE(H32:K32) -> 2.5 | N32: =IF($M$29="YA",$N$29,L32) -> 2.5 | P32: SDM
A33: 1.7 | B33: Perwujudan Peran APIP yang Efektif | H33: =H34 -> 3 | I33: =I34 -> 3 | J33: =J34 -> 3 | K33: =K34 -> 3 | L33: =AVERAGE(H33:K33) -> 3 | M33: =KK4_PENALTI!C11 -> TIDAK | N33: =IF(M33="YA",KK4_PENALTI!D11,L33) -> 3
A34: 1.7 | C34: 1 | D34: Pengawasan APIP telah dapat memberikan nilai tambah pada perbaikan pengendalian organisasi | E34: SPIP | F34: - | G34: - | H34: =KK3.1!S67 -> 3 | I34: =KK3.2!N68 -> 3 | J34: =KK3.3!N67 -> 3 | K34: =KK3.4!N117 -> 3 | L34: =AVERAGE(H34:K34) -> 3 | N34: =IF($M$33="YA",$N$33,L34) -> 3
A35: 1.8 | B35: Hubungan Kerja yang Baik dengan Instansi Pemerintah Terkait | H35: =AVERAGE(H36:H37) -> 3 | I35: =AVERAGE(I36:I37) -> 4 | J35: =AVERAGE(J36:J37) -> 4 | K35: =AVERAGE(K36:K37) -> 3.5 | L35: =AVERAGE(H35:K35) -> 3.625 | M35: =KK4_PENALTI!C12 -> TIDAK | N35: =IF(M35="YA",KK4_PENALTI!D12,L35) -> 3.625
A36: 1.8 | C36: 1 | D36: Pimpinan organisasi menjalin hubungan kerja yang baik (kemitraan) dengan instansi lain terkait dengan upaya pencapaian tujuan organisasi. | E36: SPIP | F36: - | G36: - | H36: =KK3.1!S73 -> 3 | I36: =KK3.2!N74 -> 5 | J36: =KK3.3!N73 -> 5 | K36: =KK3.4!N123 -> 4 | L36: =AVERAGE(H36:K36) -> 4.25 | N36: =IF($M$35="YA",$N$35,L36) -> 4.25
A37: 1.8 | C37: 2 | D37: Dalam rangka menciptakan hubungan kerja yang baik, instansi Pemerintah telah mengidentifikasi, menilai, dan mengelola risiko (termasuk implikasi dari transfer risiko) terkait kemitraan | E37: SPIP | F37: MRI | G37: - | H37: =KK3.1!S78 -> 3 | I37: =KK3.2!N79 -> 3 | J37: =KK3.3!N78 -> 3 | K37: =KK3.4!N128 -> 3 | L37: =AVERAGE(H37:K37) -> 3 | N37: =IF($M$35="YA",$N$35,L37) -> 3 | P37: KEMITRAAN
A38: 2.1 | B38: Identifikasi Risiko | H38: =AVERAGE(H39:H41) -> 4 | I38: =AVERAGE(I39:I41) -> 2.3333333 | J38: =AVERAGE(J39:J41) -> 2.3333333 | K38: =AVERAGE(K39:K41) -> 2.6666667 | L38: =AVERAGE(H38:K38) -> 2.8333333 | M38: =KK4_PENALTI!C14 -> TIDAK | N38: =IF(M38="YA",KK4_PENALTI!D14,L38) -> 2.8333333
A39: 2.1 | C39: 1 | D39: Pemerintah Daerah telah memiliki Kebijakan Manajemen Risiko. | E39: SPIP | F39: MRI | G39: - | H39: =KK3.1!S84 -> 4 | I39: =KK3.2!N85 -> 2 | J39: =KK3.3!N84 -> 2 | K39: =KK3.4!N134 -> 4 | L39: =AVERAGE(H39:K39) -> 3 | N39: =IF($M$38="YA",$N$38,L39) -> 3 | P39: KEBIJAKAN
A40: 2.1 | C40: 2 | D40: Risiko telah teridentifikasi dan dituangkan dalam register risiko | E40: SPIP | F40: MRI | G40: - | H40: =KK3.1!S89 -> 4 | I40: =KK3.2!N90 -> 3 | J40: =KK3.3!N89 -> 3 | K40: =KK3.4!N139 -> 2 | L40: =AVERAGE(H40:K40) -> 3 | N40: =IF($M$38="YA",$N$38,L40) -> 3 | P40: PROSES
A41: 2.1 | C41: 3 | D41: Proses manajemen risiko telah melekat pada proses bisnis Instansi Pemerintah | E41: SPIP | F41: MRI | G41: - | H41: =KK3.1!S94 -> 4 | I41: =KK3.2!N95 -> 2 | J41: =KK3.3!N94 -> 2 | K41: =KK3.4!N144 -> 2 | L41: =AVERAGE(H41:K41) -> 2.5 | N41: =IF($M$38="YA",$N$38,L41) -> 2.5 | P41: PROSES
...

Sheet Uraian NIlai Setiap Unsur
A2: Kode | B2: Uraian Subunsur | C2: No | D2: Uraian Parameter | E2: 2E NILAI | F2: KEUANGAN NILAI | G2: ASET NILAI | H2: KETAATAN NILAI | I2: KESIMPULAN NILAI
A5: 1.1 | B5: Penegakan Integritas dan Nilai Etika | E5: 3 | F5: 5 | G5: 5 | H5: 3.375 | I5: =AVERAGE(E5:H5) -> 4.09375 | J5: =AVERAGE(I5:I21) -> 3.5585938
A6: 1.2 | B6: Komitmen terhadap Kompetensi | E6: 4 | F6: 3 | G6: 3 | H6: 4 | I6: =AVERAGE(E6:H6) -> 3.5
A7: 1.3 | B7: Kepemimpinan yang Kondusif | E7: =AVERAGE(E8:E11) -> 3.25 | F7: =AVERAGE(F8:F11) -> 3 | G7: =AVERAGE(G8:G11) -> 2.75 | H7: =AVERAGE(H8:H11) -> 3 | I7: =AVERAGE(E7:H7) -> 3
A8: 1.3 | C8: 1 | D8: Pimpinan organisasi menciptakan lingkungan kerja yang kondusif untuk pencapaian tujuan organisasi. | E8: 4 | F8: 4 | G8: 3 | H8: 3
A9: 1.3 | C9: 2 | D9: Pimpinan Instansi Pemerintah mengalokasikan sumber daya untuk penerapan manajemen risiko. | E9: 3 | F9: 3 | G9: 3 | H9: 3
A10: 1.3 | C10: 3 | D10: Pimpinan Instansi Pemerintah menggunakan informasi terkait risiko dalam pengambilan keputusan | E10: 3 | F10: 2 | G10: 2 | H10: 3 | M10: Lingkungan Pengendalian | N10: =J5 -> 3.5585938
A11: 1.3 | C11: 4 | D11: Pimpinan Instansi Pemerintah mendorong penerapan manajemen risiko, melalui Penggunaan kinerja penerapan manajemen risiko sebagai indikator penilaian kinerja | E11: 3 | F11: 3 | G11: 3 | H11: 3 | M11: Penilain Risiko | N11: =J22 -> 2.8916667
A12: 1.4 | B12: Struktur Organisasi Sesuai Kebutuhan | E12: 4 | F12: 4 | G12: 4 | H12: 3 | I12: =AVERAGE(E12:H12) -> 3.75 | M12: Kegiatan Pengendalian | N12: =J32 -> 3.5681818
A13: 1.5 | B13: Pendelegasian Wewenang dan Tanggung Jawab yang Tepat | E13: 5 | F13: 5 | G13: 5 | H13: 4 | I13: =AVERAGE(E13:H13) -> 4.75 | M13: Informasi dan Komunikasi | N13: =J43 -> 3.03125
A14: 1.6 | B14: Penyusunan dan Penerapan Kebijakan yang Sehat tentang Pembinaan SDM | E14: =AVERAGE(E15:E17) -> 3 | F14: =AVERAGE(F15:F17) -> 2 | G14: =AVERAGE(G15:G17) -> 3 | H14: =AVERAGE(H15:H17) -> 3 | I14: =AVERAGE(E14:H14) -> 2.75 | M14: Pemantauan | N14: =J49 -> 2.8541667
A15: 1.6 | C15: 1 | D15: Penerapan kebijakan manajemen dan praktik pembinaan SDM sehingga dapat digunakan secara maksimal untuk mencapai tujuan organisasi | E15: 3 | F15: 2 | G15: 5 | H15: 3
A16: 1.6 | C16: 2 | D16: Pegawai telah mendapatkan fasilitas untuk meningkatkan kompetensi dan keterampilan terkait manajemen risiko | E16: 3 | F16: 2 | G16: 2 | H16: 3
A17: 1.6 | C17: 3 | D17: Pegawai memiliki kesadaran terkait manajemen risiko | E17: 3 | F17: 2 | G17: 2 | H17: 3
A18: 1.7 | B18: Perwujudan Peran APIP yang Efektif | E18: 3 | F18: 3 | G18: 3 | H18: 3 | I18: =AVERAGE(E18:H18) -> 3
A19: 1.8 | B19: Hubungan Kerja yang Baik dengan Instansi Pemerintah Terkait | E19: =AVERAGE(E20:E21) -> 3 | F19: =AVERAGE(F20:F21) -> 4 | G19: =AVERAGE(G20:G21) -> 4 | H19: =AVERAGE(H20:H21) -> 3.5 | I19: =AVERAGE(E19:H19) -> 3.625
A20: 1.8 | C20: 1 | D20: Pimpinan organisasi menjalin hubungan kerja yang baik (kemitraan) dengan instansi lain terkait dengan upaya pencapaian tujuan organisasi. | E20: 3 | F20: 5 | G20: 5 | H20: 4
A21: 1.8 | C21: 2 | D21: Dalam rangka menciptakan hubungan kerja yang baik, instansi Pemerintah telah mengidentifikasi, menilai, dan mengelola risiko (termasuk implikasi dari transfer risiko) terkait kemitraan | E21: 3 | F21: 3 | G21: 3 | H21: 3
A22: 2.1 | B22: Identifikasi Risiko | E22: =AVERAGE(E23:E25) -> 4 | F22: =AVERAGE(F23:F25) -> 2.3333333 | G22: =AVERAGE(G23:G25) -> 2.3333333 | H22: =AVERAGE(H23:H25) -> 2.6666667 | I22: =AVERAGE(E22:H22) -> 2.8333333 | J22: =AVERAGE(I22:I31) -> 2.8916667
A23: 2.1 | C23: 1 | D23: Pemerintah Daerah telah memiliki Kebijakan Manajemen Risiko. | E23: 4 | F23: 2 | G23: 2 | H23: 4
A24: 2.1 | C24: 2 | D24: Risiko telah teridentifikasi dan dituangkan dalam register risiko | E24: 4 | F24: 3 | G24: 3 | H24: 2
A25: 2.1 | C25: 3 | D25: Proses manajemen risiko telah melekat pada proses bisnis Instansi Pemerintah | E25: 4 | F25: 2 | G25: 2 | H25: 2
A26: 2.2 | B26: Analisis Risiko | E26: =AVERAGE(E27:E31) -> 3.6 | F26: =AVERAGE(F27:F31) -> 2.6 | G26: =AVERAGE(G27:G31) -> 2.6 | H26: =AVERAGE(H27:H31) -> 3 | I26: =AVERAGE(E26:H26) -> 2.95
A27: 2.2 | C27: 1 | D27: Seluruh risiko telah dianalisis dampak dan tingkat keterjadiannya | E27: 4 | F27: 3 | G27: 3 | H27: 3
A28: 2.2 | C28: 2 | D28: Instansi pemerintah telah menentukan prioritas risiko | E28: 4 | F28: 3 | G28: 3 | H28: 4
A29: 2.2 | C29: 3 | D29: Instansi Pemerintah telah menentukan rencana tindak pengendalian | E29: 4 | F29: 3 | G29: 3 | H29: 3
A30: 2.2 | C30: 4 | D30: Tindak pengendalian telah diimplementasikan | E30: 3 | F30: 3 | G30: 3 | H30: 3
A31: 2.2 | C31: 5 | D31: Tindak pengendalian efektif menurunkan risiko | E31: 3 | F31: 1 | G31: 1 | H31: 2
A32: 3.1 | B32: Reviu atas Kinerja | E32: 3 | F32: 3 | G32: 3 | H32: 3 | I32: =AVERAGE(E32:H32) -> 3 | J32: =AVERAGE(I32:I42) -> 3.5681818
A33: 3.2 | B33: Pembinaan SDM | E33: 4 | F33: 5 | G33: 4 | H33: 3 | I33: =AVERAGE(E33:H33) -> 4
A34: 3.3 | B34: Pengendalian atas Pengelolaan Sistem Informasi | E34: 4 | F34: 3 | G34: 3 | H34: 4 | I34: =AVERAGE(E34:H34) -> 3.5
A35: 3.4 | B35: Pengendalian Fisik atas Aset | E35: 4 | F35: 4 | G35: 5 | H35: 3 | I35: =AVERAGE(E35:H35) -> 4
A36: 3.5 | B36: Penetapan dan Reviu atas Indikator dan Ukuran Kinerja | E36: 4 | F36: 3 | G36: 3 | H36: 4 | I36: =AVERAGE(E36:H36) -> 3.5
A37: 3.6 | B37: Pemisahan Fungsi | E37: 4 | F37: 3 | G37: 3 | H37: 3 | I37: =AVERAGE(E37:H37) -> 3.25
A38: 3.7 | B38: Otorisasi atas Transaksi dan Kejadian yang Penting | E38: 4 | F38: 3 | G38: 3 | H38: 3 | I38: =AVERAGE(E38:H38) -> 3.25
A39: 3.8 | B39: Pencatatan yang Akurat dan Tepat Waktu atas Transaksi dan Kejadian | E39: 5 | F39: 4 | G39: 3 | H39: 4 | I39: =AVERAGE(E39:H39) -> 4
A40: 3.9 | B40: Pembatasan Akses atas Sumber Daya dan Pencatatannya | E40: 3 | F40: 3 | G40: 4 | H40: 4 | I40: =AVERAGE(E40:H40) -> 3.5
A41: 3.10 | B41: Akuntabilitas terhadap Sumber Daya dan Pencatatannya | E41: 5 | F41: 3 | G41: 3 | H41: 4 | I41: =AVERAGE(E41:H41) -> 3.75
A42: 3.11 | B42: Dokumentasi yang Baik atas SPI serta Transaksi dan Kejadian Penting | E42: 3 | F42: 4 | G42: 4 | H42: 3 | I42: =AVERAGE(E42:H42) -> 3.5
A43: 4.1 | B43: Informasi yang Relevan | E43: =AVERAGE(E44:E47) -> 3 | F43: =AVERAGE(F44:F47) -> 3 | G43: =AVERAGE(G44:G47) -> 3 | H43: =AVERAGE(H44:H47) -> 3.25 | I43: =AVERAGE(E43:H43) -> 3.0625 | J43: =AVERAGE(I43:I48) -> 3.03125
...

Sheet KKlead I KL
A1: PENJAMINAN KUALITAS HASIL PENILAIAN MANDIRI MATURITAS PENYELENGGARAAN SPIP TERINTEGRASI PEMERINTAH DAERAH … Periode Penilaian sampai dengan 30 Juni 20XX
A2: KERTAS KERJA PENILAIAN PENETAPAN TUJUAN KK LEAD I - PENETAPAN TUJUAN | E2: Indeks KK No. Disusun oleh/Tanggal Direviu oleh/Tanggal Disetujui oleh/Tanggal | H2: : : : :
A4: A. Kualitas Sasaran Strategis (KK 1)
A5: No | B5: Uraian | E5: KK | F5: Kolom | G5: Bobot | H5: Skor | I5: Skor Akhir
A7: 1 | B7: Sasaran Strategis | G7: 0.5 | H7: =AVERAGE(H8:H12) -> 0.9 | I7: =G7*H7 -> 0.45
B8: a | C8: Sasaran strategis berorientasi hasil | E8: 1.1 | F8: K | H8: ='KKE 1.1 SASTRA PEMDA'!K26 -> 0.94444444
B9: b | C9: Sasaran strategis relevan menggambarkan mandat | E9: 1.1 | F9: L | H9: ='KKE 1.1 SASTRA PEMDA'!L26 -> 1
B10: c | C10: Indikator kinerja tepat | E10: 1.1 | F10: M | H10: ='KKE 1.1 SASTRA PEMDA'!M26 -> 0.72222222
B11: d | C11: Indikator kinerja cukup untuk mengukur sasaran | E11: 1.1 | F11: N | H11: ='KKE 1.1 SASTRA PEMDA'!N26 -> 1
B12: e | C12: Target kinerja tepat | E12: 1.1 | F12: O | H12: ='KKE 1.1 SASTRA PEMDA'!O26 -> 0.83333333
A13: 2 | B13: Sasaran Program | G13: 0.5 | H13: =AVERAGE(H14:H18) -> 0.896 | I13: =G13*H13 -> 0.448
B14: a | C14: Sasaran Program berorientasi hasil | E14: 1.2 | F14: O | H14: ='KKE 1.2 SASARAN OPD'!N57 -> 1
B15: b | C15: Sasaran program relevan dengan sasaran strategis dan menggambarkan tugas dan fungsi | E15: 1.2 | F15: P | H15: ='KKE 1.2 SASARAN OPD'!O57 -> 0.78
B16: c | C16: Indikator kinerja tepat | E16: 1.2 | F16: Q | H16: ='KKE 1.2 SASARAN OPD'!P57 -> 0.94
B17: d | C17: Indikator kinerja cukup untuk mengukur sasaran | E17: 1.2 | F17: R | H17: ='KKE 1.2 SASARAN OPD'!Q57 -> 0.84
B18: e | C18: Target kinerja tepat | E18: 1.2 | F18: S | H18: ='KKE 1.2 SASARAN OPD'!R57 -> 0.92
C19: Skor Akhir | I19: =I7+I13 -> 0.898
C20: Level | I20: =(IF(I19>=90%,"5",IF(I19>=80%,"4",IF(I19>=70%,"3",IF(I19>=60%,"2","1")))))*1 -> 4
A23: B. Kualitas Strategi Pencapaian Sasaran Strategis (KK 2)
A24: No | B24: Uraian | E24: KK | F24: Kolom | G24: Bobot | H24: Skor | I24: Skor Akhir
A26: 1 | B26: Kualitas Sasaran Kegiatan | G26: 0.5 | H26: =AVERAGE(H27:H31) -> 0.94901961 | I26: =G26*H26 -> 0.4745098
B27: a | C27: Sasaran kegiatan berorientasi hasil | E27: 2.1 | F27: S | H27: ='KKE 2.1 SASKEG'!R127 -> 0.98039216
B28: b | C28: Sasaran kegiatan relevan dengan sasaran program dan menggambarkan tugas dan fungsi | E28: 2.1 | F28: T | H28: ='KKE 2.1 SASKEG'!S127 -> 0.98039216
B29: c | C29: Indikator kinerja tepat | E29: 2.1 | F29: U | H29: ='KKE 2.1 SASKEG'!T127 -> 0.91176471
B30: d | C30: Indikator kinerja cukup untuk mengukur sasaran | E30: 2.1 | F30: V | H30: ='KKE 2.1 SASKEG'!U127 -> 0.94117647
B31: e | C31: Target kinerja tepat | E31: 2.1 | F31: W | H31: ='KKE 2.1 SASKEG'!V127 -> 0.93137255
A32: 2 | B32: Kualitas Rincian Output | G32: 0.5 | H32: =AVERAGE(H33:H37) -> 1.1057143 | I32: =G32*H32 -> 0.55285714
B33: a | C33: Rincian Output relevan dengan sasaran kegiatan | E33: 2.2 | F33: U | H33: ='KK 2.2 RO'!T210 -> 1.0857143
B34: b | C34: Indikator kinerja tepat | E34: 2.2 | F34: V | H34: ='KK 2.2 RO'!U210 -> 1.0857143
B35: c | C35: Indikator kinerja cukup untuk mengukur sasaran | E35: 2.2 | F35: W | H35: ='KK 2.2 RO'!V210 -> 1.1257143
B36: d | C36: Target kinerja tepat | E36: 2.2 | F36: X | H36: ='KK 2.2 RO'!W210 -> 1.1257143
C43: Skor Akhir | I43: =I26+I32+I38 -> 1.0273669
C44: Level | I44: =(IF(I43>=90%,"5",IF(I43>=80%,"4",IF(I43>=70%,"3",IF(I43>=60%,"2","1")))))*1 -> 5
A46: Gradasi Level
C47: 1 | D47: sampai dengan 60%
C48: 2 | D48: lebih besar dari 60% s.d. 70%
C49: 3 | D49: lebih besar dari 70% s.d. 80%
C50: 4 | D50: lebih besar dari 80% s.d. 90%
C51: 5 | D51: lebih besar dari 90%

Sheet KKE 1.1 SASTRA PEMDA
A1: PENJAMINAN KUALITAS HASIL PENILAIAN MANDIRI MATURITAS PENYELENGGARAAN SPIP TERINTEGRASI KEMENTERIAN KOMUNIKASI DAN INFORMATIKA Periode Penilaian sampai dengan 30 Juni 2025
A2: KK 1.1 - PENILAIAN PENETAPAN TUJUAN - SASARAN STRATEGIS KEMENTERIAN/LEMBAGA
A3: NO | B3: URAIAN SASARAN STRATEGIS | C3: URAIAN INDIKATOR KINERJA SASARAN | D3: TARGET KINERJA | E3: SASARAN STRATEGIS | K3: PENJAMINAN KUALITAS
E4: SASTRA BERORIENTASI HASIL | F4: SASTRA RELEVAN DAN MENGGAMBARKAN MANDAT | G4: INDIKATOR KINERJA TEPAT | H4: UJI KECUKUPAN INDIKATOR | I4: TARGET KINERJA TEPAT | J4: KETERANGAN | K4: SASTRA BERORIENTASI HASIL | L4: SASTRA RELEVAN DAN MENGGAMBARKAN MANDAT | M4: INDIKATOR KINERJA TEPAT | N4: UJI KECUKUPAN INDIKATOR | O4: TARGET KINERJA TEPAT | P4: KETERANGAN
A5: 1 | B5: =A5+1 -> 2 | C5: =B5+1 -> 3 | D5: =C5+1 -> 4 | E5: =D5+1 -> 5 | F5: =E5+1 -> 6 | G5: =F5+1 -> 7 | H5: =G5+1 -> 8 | I5: =H5+1 -> 9 | ... P5: =O5+1 -> 16
A6: 1 | B6: Mempercepat Penyediaan Konektivitas Broadband Inklusif, Berkualitas, dan Terjangkau | C6: Skor Indeks Transformasi Digital Nasional Pilar Jaringan dan Infrastruktur | D6: 56,08 Nilai | E6: Y | F6: Y | G6: Y | H6: Y | I6: Y | J6: Persentase (%) kecamatan yang terjangkau infrastruktur jaringan serat optik broadband (Kumulatif) merupakan indikator bersifat outcome. Output dari IKSS ini diantaranya Penyediaan Fiber Optik pada Daerah (Kecamatan) di Kawasan Prioritas | K6: Y | L6: Y | M6: Y | N6: Y | O6: Y
A7: 2 | B7: Mempercepat Penyediaan Sistem dan Jaringan Komunikasi untuk Layanan Khusus Secara Nasional | C7: Persentase Kab/Kota yang memanfaatkan sistem penyampaian informasi kebencanaan dan kegawatdaruratan | D7: 33 Persen | E7: Y | F7: Y | G7: Y | H7: Y | I7: Y | J7: Akan diperbaiki dalam Renstra Kominfo periode berikutnya 2025-2029, mengingat Renstra tahun berjalan hanya dapat diperbaiki jika terdapat beberapa kondisi seperti kebijakan pemerintah (paling rendah dituangkan dalam Perpres), perubahan SOTK yang dituangkan dalam Perpres dan Kebijakan Nasional Perencanaan dan Penganggaran (RSPP) | K7: Y | L7: Y | M7: Y | N7: Y | O7: Y
A8: 3 | B8: Meningkatnya Pertumbuhan Ekonomi dari Pengembangan Ekosistem Digital Nasional | C8: Indeks TDN Pilar Bisnis | D8: 40,38 Nilai | E8: Y | F8: Y | G8: Y | H8: Y | I8: Y | J8: Persentase (%) rumah tangga terlayani jaringan internet akses fixed broadband terhadap total rumah Tangga (Kumulatif) merupakan indiaktor bersifat outcome. Output dari IKSS ini diantaranya | K8: Y | L8: Y | M8: T | N8: Y | O8: Y | P8: Indikator belum menunjukan efek keberlanjutan , masih menujukan impact jangan pendek
A9: 4 | B9: Mengakselerasi Kualitas dan Produktivitas Masyarakat Digital | C9: Indeks Masyarakat Digital Indonesia (IMDI) | D9: 45,23 Nilai | E9: Y | F9: Y | G9: Y | H9: Y | I9: Y | J9: Indikator ini terdapat dalam RPJMN Tahun 2020-2024. IKSS pada Renstra mengacu pada RPJMN sehingga untuk perbaikan indikator perlu dilakukan koordinasi dengan Bappenas untuk periode RPJMN berikutnya, mengingat tahun Tahun 2024 merupakan akhir periode dari RPJMN Tahun 2020-2024. | K9: Y | L9: Y | M9: Y | N9: Y | O9: Y
A10: 5 | B10: Mempercepat pemanfaatan teknologi untuk pemerintahan digital yang terpadu dan citizen centric | C10: Indeks Transformasi Digital Nasional Pilar Pemerintah | D10: 54,05 Nilai | E10: Y | F10: Y | G10: Y | H10: Y | I10: Y | J10: Memenuhi Kriteria | K10: Y | L10: Y | M10: Y | N10: Y | O10: Y
A11: 6 | B11: Menciptakan ruang digital yang aman dan berdaulat | C11: Indeks Ruang Digital Kondusif | D11: 3 Nilai | E11: Y | F11: Y | G11: Y | H11: Y | I11: Y | J11: Memenuhi Kriteria | K11: Y | L11: Y | M11: Y | N11: Y | O11: Y
A12: 7 | B12: Meningkatnya kualitas pengelolaan layanan publik Kemenkomdigi | C12: Indeks Kepuasan masyarakat terhadap layanan publik Kemenkomdigi | D12: >3.5 Nilai | E12: Y | F12: Y | G12: Y | H12: Y | I12: Y | J12: Persentase (%) jangkauan populasi penyiaran digital (Kumulatif) merupakan indikator bersifat outcome. Output dari IKSS ini diantaranya penyediaan Set Top Box (STB), pembangunan menara Transmitter, revitalisasi perangkat penyiaran digital LPP TVRI, Penyiapan Regulasi dll. | K12: Y | L12: Y | M12: T | N12: Y | O12: Y
A13: 8 | B13: Meningkatnya efektivitas penyelenggaraan informasi dan komunikasi publik | C13: Indeks Komunikasi Pembangunan dan Informasi Publik (KPIP) | D13: 71 Nilai | E13: Y | F13: Y | G13: Y | H13: Y | I13: Y | J13: Persentase (%) cakupan layanan pos (Kumulatif) merupakan indiaktor bersifat outcome, Output dari IKSS ini diantaranya penyusunan Kebijakan Pemberian Subsidi Operasional Pada Layanan Pos Universal | K13: Y | L13: Y | M13: Y | N13: Y | O13: Y
A14: 9 | B14: Mewujudkan Transformasi Internal Manajemen adaptif dan resilien | C14: Indeks Reformasi Birokrasi Kemenkomdigi | D14: 87 Nilai | E14: Y | F14: Y | G14: Y | H14: Y | I14: Y | J14: Akan diperbaiki dalam Renstra Kominfo periode berikutnya 2025-2029, mengingat Renstra tahun berjalan hanya dapat diperbaiki jika terdapat beberapa kondisi seperti kebijakan pemerintah (paling rendah dituangkan dalam Perpres), perubahan SOTK yang dituangkan dalam Perpres dan Kebijakan Nasional Perencanaan dan Penganggaran (RSPP) | K14: Y | L14: Y | M14: Y | N14: Y | O14: Y
A15: 10 | B15: Mempercepat Penyediaan Konektivitas Broadband Inklusif, Berkualitas, dan Terjangkau | C15: Indeks Pembangunan TIK (IPTIK) Nasional | D15: 6,10 Nilai | E15: Y | F15: Y | G15: Y | H15: Y | I15: Y | J15: Memenuhi Kriteria | K15: Y | L15: Y | M15: Y | N15: Y | O15: Y | P15: Indikator kinerja baru mengukur pemanfaatan spektrum frekuensi radio, tetapi tidak mengukur aspek kualitas pengelolaan layanan publik. Untuk sepenuhnya selaras dengan sasaran strategis, perlu ada indikator tambahan yang mengukur peningkatan kualitas layanan publik di bidang pos, telekomunikasi, dan informatika
A16: 11 | B16: Meningkatnya Pertumbuhan Ekonomi dari Pengembangan Ekosistem Digital Nasional | C16: Kontribusi Komdigi pada Nilai Ekonomi Digital | D16: 137.888.51 Rp | E16: Y | F16: Y | G16: Y | H16: Y | I16: Y | J16: Indikator ini terdapat dalam RPJMN Tahun 2020-2024. IKSS pada Renstra mengacu pada RPJMN sehingga untuk perbaikan indikator perlu dilakukan koordinasi dengan Bappenas untuk periode RPJMN berikutnya, mengingat tahun 2024 merupakan akhir periode dari RPJMN Tahun 2020-2024. | K16: Y | L16: Y | M16: Y | N16: Y | O16: Y
A17: 12 | B17: Mengakselerasi Kualitas dan Produktivitas Masyarakat Digital | C17: Indeks TDN pilar Masyarakat | D17: 52,08 Nilai | E17: Y | F17: Y | G17: Y | H17: Y | I17: Y | J17: Indikator ini terdapat dalam RPJMN Tahun 2020-2024 tagging PN 7 (Memperkuat Stabilitas Polhankam dan Transformasi pelayanan Publik). Seharusnya indikator ini masuk ke dalam PN 3 (Meningkatkan Sumber Daya Manusia Berkualitas dan Berdaya Saing) terkait Peningkatan Sumber Daya Manusia dan Daya Saing. Untuk perbaikan tagging indikator perlu dilakukan koordinasi dengan Bappenas untuk periode RPJMN berikutnya, mengingat tahun 2024 merupakan akhir periode dari RPJMN Tahun 2020-2024. | K17: Y | L17: Y | M17: T | N17: Y | O17: Y | P17: Indikator kinerja masih bersifat umum
A18: 13 | B18: Mewujudkan Transformasi Internal Manajemen adaptif dan resilien | C18: Indeks Opini Badan Pemeriksaan Keuangan (BPK) atas Laporan Keuangan | D18: WTP Nilai | E18: Y | F18: Y | G18: Y | H18: Y | I18: Y | J18: Memenuhi Kriteria | K18: Y | L18: Y | M18: T | N18: Y | O18: Y | P18: indikator kinerja masih belum menggambarkan transformasi bersifat internal karena aspek resiliensi cakupannya bukan hanya laporan keuangan akan tetapi cakupannya sangat luas seperti Tata Kelola, SDM, Teknologi dan infrastruktur digital dsb
A19: 14 | B19: Mempercepat Penyediaan Konektivitas Broadband Inklusif, Berkualitas, dan Terjangkau | C19: Peningkatan kota/kab yang memiliki internet broadband berkecepatan giga (min. 1 Gbps) | D19: TBD Nilai | E19: Y | F19: Y | G19: Y | H19: Y | I19: T | J19: Target Kinerja masih dalam tahap diskusi dengan Ditjen Terkait | K19: Y | L19: Y | M19: Y | N19: Y | O19: T
A20: 15 | B20: Meningkatnya Pertumbuhan Ekonomi dari Pengembangan Ekosistem Digital Nasional | C20: Kontribusi sektor informasi dan komunikasi terhadap PDB | D20: 4,3 Persen | E20: Y | F20: Y | G20: Y | H20: Y | I20: Y | J20: Memenuhi Kriteria | K20: Y | L20: Y | M20: Y | N20: Y | O20: Y
A21: 16 | B21: Mengakselerasi Kualitas dan Produktivitas Masyarakat Digital | C21: Peningkatan Tenaga Kerja Sektor TIK (kumulatif) (%) | D21: 1310 Persen | E21: Y | F21: Y | G21: Y | H21: Y | I21: T | J21: Target direvisi menjadi sebesar 3,2% | K21: Y | L21: Y | M21: Y | N21: Y | O21: T
A22: 17 | B22: Mewujudkan Transformasi Internal Manajemen adaptif dan resilien | C22: Tingkat Dampak Kerja Sama Internasional terhadap Kolaborasi Pemangku Kebijakan Digital | D22: 4 Nilai | E22: Y | F22: Y | G22: Y | H22: Y | I22: Y | J22: Memenuhi Kriteria | K22: Y | L22: Y | M22: Y | N22: Y | O22: Y
A23: 18 | B23: Mengakselerasi Kualitas dan Produktivitas Masyarakat Digital | C23: Tingkat ASN yang memiliki kompetensi digital | D23: TBD Nilai | E23: Y | F23: Y | G23: Y | H23: Y | I23: T | J23: Target masih didiskusikan dengan BPSDM | K23: T | L23: Y | M23: T | N23: Y | O23: T | P23: belum menunjukan indikator yang efektif
E24: =COUNTIF(E6:E23,"Y") -> 18 | F24: =COUNTIF(F6:F23,"Y") -> 18 | G24: =COUNTIF(G6:G23,"Y") -> 18 | H24: =COUNTIF(H6:H23,"Y") -> 18 | I24: =COUNTIF(I6:I23,"Y") -> 15 | K24: =COUNTIF(K6:K23,"Y") -> 17 | L24: =COUNTIF(L6:L23,"Y") -> 18 | M24: =COUNTIF(M6:M23,"Y") -> 13 | N24: =COUNTIF(N6:N23,"Y") -> 18 | O24: =COUNTIF(O6:O23,"Y") -> 15
E25: =COUNTA(E6:E23) -> 18 | F25: =COUNTA(F6:F23) -> 18 | G25: =COUNTA(G6:G23) -> 18 | H25: =COUNTA(H6:H23) -> 18 | I25: =COUNTA(I6:I23) -> 18 | K25: =COUNTA(K6:K23) -> 18 | L25: =COUNTA(L6:L23) -> 18 | M25: =COUNTA(M6:M23) -> 18 | N25: =COUNTA(N6:N23) -> 18 | O25: =COUNTA(O6:O23) -> 18
E26: =E24/E25 -> 1 | F26: =F24/F25 -> 1 | G26: =G24/G25 -> 1 | H26: =H24/H25 -> 1 | I26: =I24/I25 -> 0.83333333 | K26: =K24/K25 -> 0.94444444 | L26: =L24/L25 -> 1 | M26: =M24/M25 -> 0.72222222 | N26: =N24/N25 -> 1 | O26: =O24/O25 -> 0.83333333

Sheet KKE 1.2 SASARAN OPD
A1: PENILAIAN MANDIRI MATURITAS PENYELENGGARAAN SPIP Kementerian Komunikasi dan Digital RI Periode penilaian 01 Juli 2024 s.d 30 Juni 2025
A2: KK 1.2 - PENILAIAN PENETAPAN TUJUAN - SASARAN PROGRAM KEMENTERIAN LEMBAGA
A3: No | B3: SASARAN STRATEGIS | D3: KUALITAS SASARAN PROGRAM | M3: Keterangan | N3: PENJAMINAN KUALITAS
B4: URAIAN SASARAN STRATEGIS | C4: SASTRA RELEVAN DAN MENGGAMBARKAN MANDAT | D4: NAMA PROGRAM | E4: URAIAN SASARAN PROGRAM | F4: INDIKATOR KINERJA SASARAN | G4: TARGET KINERJA | H4: SASARAN PROGRAM BERORIENTASI HASIL | I4: SASPRO RELEVAN DENGAN SASTRA DAN MENGGAMBARKAN TUGAS DAN FUNGSI | J4: INDIKATOR KINERJA TEPAT | K4: UJI KECUKUPAN INDIKATOR | L4: TARGET KINERJA TEPAT | N4: SASARAN OPD BERORIENTASI HASIL | O4: SASTRA OPD RELEVAN DAN MENGGAMBARKAN MANDAT | P4: INDIKATOR KINERJA TEPAT | Q4: UJI KECUKUPAN INDIKATOR | R4: TARGET KINERJA TEPAT | S4: KETERANGAN
A5: 1 | B5: Mempercepat Penyediaan Konektivitas Broadband Inklusif, Berkualitas, dan Terjangkau | C5: Y | D5: Program Pengembangan dan Penguatan Infrastruktur Digital | E5: Meningkatnya Kualitas Internet Broadband Nasional | F5: Rata-rata kecepatan internet mobile broadband di wilayah Indonesia | G5: 45 Mbps | H5: Y | I5: Y | J5: Y | K5: Y | L5: Y | M5: - | N5: Y | O5: Y | P5: Y | Q5: Y | R5: Y
A6: 2 | B6: Mempercepat Penyediaan Konektivitas Broadband Inklusif, Berkualitas, dan Terjangkau | C6: Y | D6: Program Pengembangan dan Penguatan Infrastruktur Digital | E6: Meningkatnya Kualitas Internet Broadband Nasional | F6: Kecepatan Internet Jaringan Pita Lebar Tetap (Fixed Broadband) | G6: 32 Mbps | H6: Y | I6: Y | J6: Y | K6: Y | L6: Y | M6: - | N6: Y | O6: Y | P6: Y | Q6: Y | R6: Y
A7: 3 | B7: Mempercepat Penyediaan Konektivitas Broadband Inklusif, Berkualitas, dan Terjangkau | C7: Y | D7: Program Pengembangan dan Penguatan Infrastruktur Digital | E7: Meningkatnya Kualitas Internet Broadband Nasional | F7: Persentase (%) Penanganan Gangguan Spektrum Frekuensi Radio (SFR) | G7: 95 Persen | H7: Y | I7: Y | J7: Y | K7: Y | L7: Y | M7: - | N7: Y | O7: Y | P7: Y | Q7: T | R7: Y | S7: belum menunjukan aspek kualitas dan kuantitas
A8: 4 | B8: Mempercepat Penyediaan Konektivitas Broadband Inklusif, Berkualitas, dan Terjangkau | C8: Y | D8: Program Pengembangan dan Penguatan Infrastruktur Digital | E8: Meningkatnya Kualitas Internet Broadband Nasional | F8: Persentase (%) Tingkat Kepatuhan Standar Teknis Alat dan /atau Perangkat Telekomunikasi dan Digital | G8: 75 persen | H8: Y | I8: Y | J8: Y | K8: Y | L8: Y | M8: - | N8: Y | O8: Y | P8: Y | Q8: Y | R8: Y
A9: 5 | B9: Mempercepat Penyediaan Konektivitas Broadband Inklusif, Berkualitas, dan Terjangkau | C9: Y | D9: Program Pengembangan dan Penguatan Infrastruktur Digital | E9: Meningkatnya Kualitas Internet Broadband Nasional | F9: Persentase (%) Tersedianya Layanan Akses Internet Pita Lebar Dengan Kecepatan yang Lebih Tinggi Menggunakan Spektrum Frekuensi Radio (SFR) | G9: 100 Persen | H9: Y | I9: Y | J9: Y | K9: Y | L9: Y | M9: - | N9: Y | O9: Y | P9: T | Q9: T | R9: Y | S9: Indikator : tingkat efisiensi
A10: 6 | B10: Mempercepat Penyediaan Konektivitas Broadband Inklusif, Berkualitas, dan Terjangkau | C10: Y | D10: Program Pengembangan dan Penguatan Infrastruktur Digital | E10: Meningkatnya Kualitas Internet Broadband Nasional | F10: Persentase (%) Tindak Lanjut Hasil Pengawasan terhadap Kualitas Layanan dan Aduan Masyarakat | G10: 100 Persen | H10: Y | I10: Y | J10: Y | K10: Y | L10: Y | M10: - | N10: Y | O10: Y | P10: T | Q10: T | R10: Y | S10: Indikator : tingkat efektivitas
A11: 7 | B11: Mempercepat Penyediaan Konektivitas Broadband Inklusif, Berkualitas, dan Terjangkau | C11: Y | D11: Program Pengembangan dan Penguatan Infrastruktur Digital | E11: Mempercepat Terwujudnya Coverage Broadband yang Merata ke Seluruh Indonesia | F11: Persentase (%) Cakupan Luas Pemukiman yang Tercover Layanan Mobile Broadband | G11: 97,6 Persen | H11: Y | I11: Y | J11: Y | K11: Y | L11: Y | M11: Nomenklatur Sasaran Program telah direvisi menjadi "Meningkatnya Coverage Broadband yang menjangkau ke seluruh indonesia" | N11: Y | O11: Y | P11: T | Q11: T | R11: Y | S11: Indikator : harusnya berfokus ke pemerataan jangkauan terhadap layanan belum menunjukan aspek kebijkan yang lebih jelas
A12: 8 | B12: Mempercepat Penyediaan Konektivitas Broadband Inklusif, Berkualitas, dan Terjangkau | C12: Y | D12: Program Pengembangan dan Penguatan Infrastruktur Digital | E12: Mempercepat Terwujudnya Coverage Broadband yang Merata ke Seluruh Indonesia | F12: Persentase (%) Jangkauan Jaringan Fiber Optik Kecamatan | G12: 71,5 Persen | H12: Y | I12: Y | J12: Y | K12: Y | L12: Y | M12: Nomenklatur Indikator telah direvisi menjadi "Persentase jaringan fiber optic menjangkau desa/kelurahan" | N12: Y | O12: Y | P12: Y | Q12: Y | R12: Y
A13: 9 | B13: Mempercepat Penyediaan Konektivitas Broadband Inklusif, Berkualitas, dan Terjangkau | C13: Y | D13: Program Pengembangan dan Penguatan Infrastruktur Digital | E13: Meningkatnya Penetrasi dan Utilisasi (Take Up) Internet Broadband | F13: Persentase (%) Peningkatan Jumlah Pelanggan Jaringan Tetap Pita Lebar Nasional | G13: 2,43 Persen | H13: Y | I13: Y | J13: Y | K13: Y | L13: Y | M13: Indikator telah diubah menjadi "Persentase (%) Tersedianya Akses Internet di Sektor Publik" | N13: Y | O13: Y | P13: Y | Q13: Y | R13: Y
A14: 10 | B14: Mempercepat Penyediaan Konektivitas Broadband Inklusif, Berkualitas, dan Terjangkau | C14: Y | D14: Program Pengembangan dan Penguatan Infrastruktur Digital | E14: Mewujudkan Industri Telekomunikasi dan Data Center yang berkelanjutan | F14: Rasio Biaya Hak Penggunaan (BHP) Spektrum Frekuensi Radio (SFR) terhadap Gross Revenue Industri dalam Rangka Keberlanjutan Industri Telekomunikasi | G14: 9,7 Persen | H14: Y | I14: Y | J14: Y | K14: Y | L14: Y | M14: - | N14: Y | O14: Y | P14: Y | Q14: T | R14: Y
A15: 11 | B15: Mempercepat Penyediaan Konektivitas Broadband Inklusif, Berkualitas, dan Terjangkau | C15: Y | D15: Program Pengembangan dan Penguatan Infrastruktur Digital | E15: Mewujudkan Industri Telekomunikasi dan Data Center yang berkelanjutan | F15: Kapasitas Data Center per kapita (Watt per kapita) | G15: 0,85 Watt Per Kapita | H15: Y | I15: Y | J15: Y | K15: Y | L15: Y | M15: Terdapat perubahan target menjadi "1,47 Watt per kapita" | N15: Y | O15: T | P15: Y | Q15: T | R15: Y | S15: ditambahkan tingkat ketersedian agar dapat terlihat kuantitasnya
A16: 12 | B16: Mempercepat Penyediaan Konektivitas Broadband Inklusif, Berkualitas, dan Terjangkau | C16: Y | D16: Program Pengembangan dan Penguatan Infrastruktur Digital | E16: Meningkatnya Pengembangan Industri Perangkat Digital yang Aman | F16: Persentase (%) Pengembangan Industri Perangkat Digital Dalam Negeri | G16: 20 Persen | H16: Y | I16: Y | J16: Y | K16: Y | L16: Y | M16: Nomenklatur Indikator mengalami perubahan menjadi "Nilai ekspor jasa telekomunikasi, komputer, dan informasi " | N16: Y | O16: T | P16: Y | Q16: Y | R16: Y
A17: 13 | B17: Mempercepat Penyediaan Konektivitas Broadband Inklusif, Berkualitas, dan Terjangkau | C17: Y | D17: Program Pengembangan dan Penguatan Infrastruktur Digital | E17: Meningkatnya cakupan dan kualitas layanan broadband di wilayah non komersial | F17: Jumlah Desa di Wilayah 3T Yang Mendapatkan Akses Seluler 4G (Kumulatif) | G17: 1.044 Lokasi | H17: Y | I17: Y | J17: Y | K17: Y | L17: Y | M17: Pada Rancangan Renstra 2025-2029, sasaran program & indikator program dari BAKTI bergabung bersama Ditjen Infrastruktur Digital | N17: Y | O17: Y | P17: Y | Q17: Y | R17: Y
A18: 14 | B18: Mempercepat Penyediaan Konektivitas Broadband Inklusif, Berkualitas, dan Terjangkau | C18: Y | D18: Program Pengembangan dan Penguatan Infrastruktur Digital | E18: Meningkatnya cakupan dan kualitas layanan broadband di wilayah non komersial | F18: Jumlah Lokasi Penyediaan Akses Internet di Wilayah Tertinggal, Terdepan, Terluar, Kawasan Prioritas, dan Lokasi Layanan Publik (Kumulatif) | G18: 27.869 Lokasi | H18: Y | I18: Y | J18: Y | K18: Y | L18: Y | M18: Pada Rancangan Renstra 2025-2029, sasaran program & indikator program dari BAKTI bergabung bersama Ditjen Infrastruktur Digital | N18: Y | O18: Y | P18: Y | Q18: Y | R18: Y
A19: 15 | B19: Mempercepat Penyediaan Konektivitas Broadband Inklusif, Berkualitas, dan Terjangkau | C19: Y | D19: Program Pengembangan dan Penguatan Infrastruktur Digital | E19: Meningkatnya cakupan dan kualitas layanan broadband di wilayah non komersial | F19: Persentase (%) Pemanfaatan Kapasitas Palapa Ring Barat 70%, Palapa Ring Tengah 45%, Palapa Ring Timur 45%, dengan Service Level Agreement (SLA) Minimal 95% | G19: 53 Persen | H19: Y | I19: Y | J19: Y | K19: Y | L19: Y | M19: Pada Rancangan Renstra 2025-2029, sasaran program & indikator program dari BAKTI bergabung bersama Ditjen Infrastruktur Digital | N19: Y | O19: Y | P19: Y | Q19: Y | R19: Y
A20: 16 | B20: Mempercepat Penyediaan Konektivitas Broadband Inklusif, Berkualitas, dan Terjangkau | C20: Y | D20: Program Pengembangan dan Penguatan Infrastruktur Digital | E20: Meningkatnya cakupan dan kualitas layanan broadband di wilayah non komersial | F20: Jumlah Kapasitas Penyediaan Satelit Multifungsi (SATRIA-1) (Kumulatif) | G20: 150 Gbps | H20: Y | I20: Y | J20: Y | K20: Y | L20: Y | M20: Pada Rancangan Renstra 2025-2029, sasaran program & indikator program dari BAKTI bergabung bersama Ditjen Infrastruktur Digital | N20: Y | O20: Y | P20: Y | Q20: Y | R20: Y
A21: 17 | B21: Mempercepat Penyediaan Konektivitas Broadband Inklusif, Berkualitas, dan Terjangkau | C21: Y | D21: Program Pengembangan dan Penguatan Infrastruktur Digital | E21: Meningkatnya cakupan dan kualitas layanan broadband di wilayah non komersial | F21: Jumlah Solusi Ekosistem Dalam Rangka Peningkatan Produktivitas masyarakat melalui Pemanfaatan Infrastruktur Dan Penguatan Ekosistem di WPUTI (Kumulatif) | G21: 15 Kelompok Masyarakat | H21: Y | I21: Y | J21: Y | K21: Y | L21: Y | M21: Pada Rancangan Renstra 2025-2029, sasaran program & indikator program dari BAKTI bergabung bersama Ditjen Infrastruktur Digital | N21: Y | O21: Y | P21: Y | Q21: Y | R21: Y
A22: 18 | B22: Mempercepat Penyediaan Sistem dan Jaringan Komunikasi untuk Layanan Khusus Secara Nasional | C22: Y | D22: Program Pengembangan dan Penguatan Infrastruktur Digital | E22: Meningkatnya Akselerasi Penyediaan Infrastruktur dan Sumber Daya untuk Layanan Khusus | F22: Persentase (%) Kabupaten/Kota yang Terfasilitasi Layanan Infrastruktur Telekomunikasi untuk Keperluan Perlindungan Masyarakat dan Penanggulangan Bencana | G22: 33,2 Persen (kumulatif) | H22: Y | I22: Y | J22: Y | K22: Y | L22: Y | M22: Sasaran Program telah berubah menjadi " Presentase Kab/Kota yang sudah terintegrasi Sistem Informasi dan Infrastruktur Jaringan Komunikasi Layanan Khusus Publik" dan target telah direvisi menjadi "35%" | N22: Y | O22: Y | P22: Y | Q22: Y | R22: Y
A23: 19 | B23: Meningkatnya Pertumbuhan Ekonomi dari Pengembangan Ekosistem Digital Nasional | C23: Y | D23: Program Pengembangan dan Penguatan Ekosistem dan Ruang Digital | E23: Meningkatnya Pertumbuhan Industri Pos Logistik dan Penyiaran | F23: Persentase pertumbuhan sektor penyiaran | G23: TBD TBD | H23: Y | I23: Y | J23: Y | K23: Y | L23: Y | M23: - | N23: Y | O23: Y | P23: Y | Q23: Y | R23: T
A24: 20 | B24: Meningkatnya Pertumbuhan Ekonomi dari Pengembangan Ekosistem Digital Nasional | C24: Y | D24: Program Pengembangan dan Penguatan Ekosistem dan Ruang Digital | E24: Meningkatnya Pertumbuhan Industri Gim dan Startup Digital Nasional | F24: Tingkat kesuksesan startup nasional / success rate startup | G24: 7 Persen | H24: Y | I24: Y | J24: Y | K24: Y | L24: Y | M24: - | N24: Y | O24: Y | P24: Y | Q24: Y | R24: Y
A25: 21 | B25: Meningkatnya Pertumbuhan Ekonomi dari Pengembangan Ekosistem Digital Nasional | C25: Y | D25: Program Pengembangan dan Penguatan Ekosistem dan Ruang Digital | E25: Meningkatnya Pertumbuhan Industri Gim dan Startup Digital Nasional | F25: Kontribusi startup digital terhadap nilai ekonomi digital | G25: TBD TBD | H25: Y | I25: Y | J25: Y | K25: Y | L25: Y | M25: Sasaran program berubah menjadi "Meningkatnya Penciptaan Nilai Ekonomi Digital dengan Penguatan Ekosistem Digital Nasional" dan target masih didiskusikan dengan Ditjen terkait | N25: Y | O25: Y | P25: Y | Q25: T | R25: T | S25: indikator belum dapat diukur
A26: 22 | B26: Meningkatnya Pertumbuhan Ekonomi dari Pengembangan Ekosistem Digital Nasional | C26: Y | D26: Program Pengembangan dan Penguatan Ekosistem dan Ruang Digital | E26: Meningkatnya Pertumbuhan Industri Gim dan Startup Digital Nasional | F26: Kontribusi Komdigi dalam persentase pertumbuhan gim nasional | G26: TBD TBD | H26: Y | I26: Y | J26: Y | K26: Y | L26: Y | M26: Sasaran program berubah menjadi "Meningkatnya Penciptaan Nilai Ekonomi Digital dengan Penguatan Ekosistem Digital Nasional" dan target masih didiskusikan dengan Ditjen terkait | N26: Y | O26: Y | P26: Y | Q26: T | R26: T | S26: indikator belum dapat diukur
A27: 23 | B27: Meningkatnya Pertumbuhan Ekonomi dari Pengembangan Ekosistem Digital Nasional | C27: Y | D27: Program Pengembangan dan Penguatan Ekosistem dan Ruang Digital | E27: Meningkatnya Pertumbuhan Industri Pos Logistik dan Penyiaran | F27: Persentase pertumbuhan sektor pos | G27: 9.5 Persen | H27: Y | I27: Y | J27: Y | K27: Y | L27: Y | M27: Indikator Program berubah menjadi "Pertumbuhan Sektor Pos Logistik" | N27: Y | O27: Y | P27: Y | Q27: Y | R27: Y
A28: 24 | B28: Meningkatnya Pertumbuhan Ekonomi dari Pengembangan Ekosistem Digital Nasional | C28: Y | D28: Program Pengembangan dan Penguatan Ekosistem dan Ruang Digital | E28: Meningkatnya Produktivitas di Sektor-sektor Prioritas dengan Pemanfaatan Teknologi Digital | F28: Persentase peningkatan produktivitas pelaku usaha di sektor produktif melalui pemanfaatan teknologi digital | G28: 10 Persen | H28: Y | I28: Y | J28: Y | K28: Y | L28: Y | M28: Indikator berubah menjadi "Persentase tingkat pertumbuhan pelaku usaha bidang teknologi baru" | N28: Y | O28: Y | P28: Y | Q28: Y | R28: Y
A29: 25 | B29: Meningkatnya Pertumbuhan Ekonomi dari Pengembangan Ekosistem Digital Nasional | C29: Y | D29: Program Pengembangan dan Penguatan Ekosistem dan Ruang Digital | E29: Meningkatnya Produktivitas di Sektor-sektor Prioritas dengan Pemanfaatan Teknologi Digital | F29: Persentase rata-rata peningkatan produktivitas sektor pasca adopsi digital | G29: TBD TBD | H29: Y | I29: Y | J29: Y | K29: Y | L29: Y | M29: - | N29: Y | O29: Y | P29: Y | Q29: Y | R29: T
A30: 26 | B30: Meningkatnya efektivitas penyelenggaraan informasi dan komunikasi publik | C30: Y | D30: Program Komunikasi Publik dan Media | E30: Meningkatnya efektivitas penyelenggaraan komunikasi publik nasional | F30: Tingkat jangkauan komunikasi publik | G30: 75 Persen | H30: Y | I30: Y | J30: Y | K30: Y | L30: Y | M30: - | N30: Y | O30: Y | P30: Y | Q30: Y | R30: Y
A31: 27 | B31: Meningkatnya efektivitas penyelenggaraan informasi dan komunikasi publik | C31: Y | D31: Program Komunikasi Publik dan Media | E31: Meningkatnya efektivitas penyelenggaraan komunikasi publik nasional | F31: Tingkat pemerataan aksesibilitas informasi publik pada kelompok masyarakat marginal (mencakup masyarakat di wilayah 3T, kelompok rentan, dan penyandang disabilitas) | G31: 75 Persen | H31: Y | I31: Y | J31: Y | K31: Y | L31: Y | M31: - | N31: Y | O31: Y | P31: Y | Q31: Y | R31: Y
A32: 28 | B32: Meningkatnya efektivitas penyelenggaraan informasi dan komunikasi publik | C32: Y | D32: Program Komunikasi Publik dan Media | E32: Meningkatnya efektivitas penyelenggaraan komunikasi publik nasional | F32: Tingkat kepuasan masyarakat terhadap akses dan kualitas informasi publik | G32: 75 Persen | H32: Y | I32: Y | J32: Y | K32: Y | L32: Y | M32: - | N32: Y | O32: Y | P32: Y | Q32: Y | R32: Y
A33: 29 | B33: Meningkatnya efektivitas penyelenggaraan informasi dan komunikasi publik | C33: Y | D33: Program Komunikasi Publik dan Media | E33: Meningkatnya keterbukaan informasi publik | F33: Tingkat kepuasan masyarakat terhadap keterbukaan informasi | G33: 76 Persen | H33: Y | I33: Y | J33: Y | K33: Y | L33: Y | M33: - | N33: Y | O33: Y | P33: Y | Q33: Y | R33: Y
A34: 30 | B34: Meningkatnya efektivitas penyelenggaraan informasi dan komunikasi publik | C34: Y | D34: Program Komunikasi Publik dan Media | E34: Meningkatnya kualitas ekosistem media yang terpercaya | F34: Persentase (%) peningkatan kualitas pengelolaan media | G34: 65 Persen | H34: Y | I34: Y | J34: Y | K34: Y | L34: Y | M34: - | N34: Y | O34: Y | P34: Y | Q34: Y | R34: Y
A35: 31 | B35: Meningkatnya efektivitas penyelenggaraan informasi dan komunikasi publik | C35: Y | D35: Program Komunikasi Publik dan Media | E35: Meningkatnya efektivitas penyelenggaraan komunikasi publik nasional | F35: Keberhasilan pengelolaan isu dan situasi krisis komunikasi publik | G35: 65 Persen | H35: Y | I35: Y | J35: Y | K35: Y | L35: Y | M35: - | N35: Y | O35: Y | P35: Y | Q35: Y | R35: Y
A36: 32 | B36: Meningkatnya kualitas pengelolaan layanan publik Kemenkomdigi | C36: Y | D36: Program Pengembangan dan Penguatan Infrastruktur Digital | E36: Meningkatnya Kualitas Layanan Publik Bidang Infrastruktur Digital | F36: Persentase (%) Realisasi Penerimaan PNBP Infrastruktur Digital | G36: 100 Persen | H36: Y | I36: Y | J36: Y | K36: Y | L36: Y | M36: - | N36: Y | O36: Y | P36: Y | Q36: Y | R36: Y
A37: 33 | B37: Meningkatnya kualitas pengelolaan layanan publik Kemenkomdigi | C37: Y | D37: Program Pengembangan dan Penguatan Infrastruktur Digital | E37: Meningkatnya Kualitas Layanan Publik Bidang Infrastruktur Digital | F37: Indeks Integritas Pelayanan Publik (IIPP) Bidang Infrastruktur Digital | G37: 8,5 Nilai | H37: Y | I37: Y | J37: Y | K37: Y | L37: Y | M37: - | N37: Y | O37: Y | P37: Y | Q37: Y | R37: Y
A38: 34 | B38: Meningkatnya kualitas pengelolaan layanan publik Kemenkomdigi | C38: Y | D38: Program Pengembangan dan Penguatan Infrastruktur Digital | E38: Meningkatnya Kualitas Layanan Publik Bidang Infrastruktur Digital | F38: Indeks Kepuasan Masyarakat (IKM) Terhadap Layanan Publik Bidang Infrastruktur Digital | G38: 3,6 Nilai | H38: Y | I38: Y | J38: Y | K38: Y | L38: Y | M38: - | N38: Y | O38: Y | P38: Y | Q38: Y | R38: Y
... A54: 52 | B54: Mewujudkan Transformasi Internal Manajemen adaptif dan resilien | C54: Y | D54: Program Dukungan Manajemen | E54: Meningkatkan efektivitas dan efisiensi pengelolaan birokrasi di Komdigi untuk mendukung transformasi digital nasional | F54: Nilai Kualitas Pelaporan Keuangan Unit Akuntansi Pembantu Pengguna Anggaran Eselon I (UAPPA Esselon 1) atas Laporan Keuangan BAKTI Tahun 2024 | G54: 80 Nilai | H54: Y | I54: Y | J54: Y | K54: Y | L54: Y | M54: Indikator ini telah diturunkan ke level kegiatan pada rancangan akhir renstra 2025-2029 | N54: Y | O54: T | P54: Y | Q54: Y | R54: Y
H55: 52 | I55: =COUNTIF(I5:I54,"Y") -> 50 | J55: =COUNTIF(J5:J54,"Y") -> 50 | K55: =COUNTIF(K5:K54,"Y") -> 50 | L55: =COUNTIF(L5:L54,"Y") -> 50 | N55: =COUNTIF(N5:N54,"Y") -> 50 | O55: =COUNTIF(O5:O54,"Y") -> 39 | P55: =COUNTIF(P5:P54,"Y") -> 47 | Q55: =COUNTIF(Q5:Q54,"Y") -> 42 | R55: =COUNTIF(R5:R54,"Y") -> 46
...

Sheet KKE 2.1 SASKEG
A1: PENJAMINAN KUALITAS HASIL PENILAIAN MANDIRI MATURITAS PENYELENGGARAAN SPIP TERINTEGRASI KEMENTERIAN KOMUNIKASI DAN INFORMATIKA Periode Penilaian sampai dengan 30 Juni 2024
A2: KK 2.1 - PENILAIAN PENETAPAN TUJUAN - SASARAN KEGIATAN
A3: NO | B3: SASARAN STRATEGIS | D3: SASARAN PROGRAM | G3: UNIT KERJA | H3: NAMA KEGIATAN | I3: SASARAN KEGIATAN | J3: INDIKATOR KINERJA | K3: TARGET KINERJA | L3: KUALITAS SASARAN KEGIATAN | Q3: KETERANGAN | R3: PENJAMINAN KUALITAS | W3: KETERANGAN
B4: URAIAN SASARAN STRATEGIS | C4: SASTRA RELEVAN DAN MENGGAMBARKAN MANDAT | D4: NAMA PROGRAM | E4: URAIAN SASARAN PROGRAM | F4: SASPRO RELEVAN DENGAN SASTRA DAN MENGGAMBARKAN TUGAS DAN FUNGSI | L4: SASTRA KEGIATAN BERORIENTASI HASIL | M4: SASKEG RELEVAN DENGAN SASPRO DAN MENGGAMBARKAN TUGAS DAN FUNGSI | N4: INDIKATOR KINERJA TEPAT | O4: UJI KECUKUPAN INDIKATOR | P4: TARGET KINERJA TEPAT | R4: SASTRA KEGIATAN BERORIENTASI HASIL | S4: SASKEG RELEVAN DENGAN SASPRO DAN MENGGAMBARKAN TUGAS DAN FUNGSI | T4: INDIKATOR KINERJA TEPAT | U4: UJI KECUKUPAN INDIKATOR | V4: TARGET KINERJA TEPAT
A5: 1 | B5: =A5+1 -> 2 | C5: =B5+1 -> 3 | D5: =C5+1 -> 4 | E5: =D5+1 -> 5 | F5: =E5+1 -> 6 | H5: =G5+1 -> 1 | I5: =H5+1 -> 2 | J5: 11 | K5: 12 | L5: =K5+1 -> 13 | M5: =L5+1 -> 14 | N5: =M5+1 -> 15 | O5: =N5+1 -> 16 | P5: =O5+1 -> 17 | Q5: =P5+1 -> 18 | R5: =Q5+1 -> 19 | S5: =R5+1 -> 20 | ... W5: =V5+1 -> 24
A6: Direktorat Jenderal Komunikasi Publik dan Media
A7: 1 | B7: Meningkatnya efektivitas penyelenggaraan informasi dan komunikasi publik | C7: Y | D7: Program Komunikasi Publik dan Media | E7: Meningkatnya efektivitas penyelenggaraan komunikasi publik nasional | F7: Y | G7: Direktorat Informasi Publik | H7: Penguatan Komunikasi dan Informasi Publik Nasional | I7: Menyediakan Konten Informasi Publik yang Berkualitas, Relevan, dan Kredibel | J7: Tingkat kepatuhan standar konten informasi publik dan manajemen aset K/L/D | K7: 0.7 | L7: T | M7: Y | N7: Y | O7: Y | P7: Y | R7: T | S7: Y | T7: Y | U7: Y | V7: Y | W7: -Saskeg masih berorientasi pada proses -Indikator untuk mengkukur kualitas, relevansi, dan kredibilitas seperti apa? | Z7: Saskeg merupakan turunan dari Draft Perpres SKPN. Indeks komunikasi pembangunan dan informasi publik mengukur 5 aspek, bisa terukur kualittasnya. -Manajemen aset berupa informasi | AA7: Cara mengkukur kualitas, relevansi, dan kredibilitas. Apa indikatornya?
